{"timestamp": "2025-07-19T18:48:10.028375Z", "level": "INFO", "logger": "test_module", "message": "This is an info message", "correlation_id": "c8184933-5ee5-402d-b278-adf556211356", "module": "test_error_handling", "function": "test_logging", "line": 27, "process_id": 15344, "thread_id": 8712871680, "extra": {"taskName": null}}
{"timestamp": "2025-07-19T18:48:10.028510Z", "level": "WARNING", "logger": "test_module", "message": "This is a warning message", "correlation_id": "c8184933-5ee5-402d-b278-adf556211356", "module": "test_error_handling", "function": "test_logging", "line": 28, "process_id": 15344, "thread_id": 8712871680, "extra": {"taskName": null}}
{"timestamp": "2025-07-19T18:48:10.028559Z", "level": "ERROR", "logger": "test_module", "message": "This is an error message", "correlation_id": "c8184933-5ee5-402d-b278-adf556211356", "module": "test_error_handling", "function": "test_logging", "line": 29, "process_id": 15344, "thread_id": 8712871680, "extra": {"taskName": null}}
{"timestamp": "2025-07-19T18:48:10.133881Z", "level": "INFO", "logger": "test_module", "message": "Processing step 'test_step' completed in 0.10s", "correlation_id": "c8184933-5ee5-402d-b278-adf556211356", "module": "logging_config", "function": "log_processing_step", "line": 268, "process_id": 15344, "thread_id": 8712871680, "extra": {"taskName": null, "processing_step": "test_step", "step_status": "completed", "duration_seconds": 0.1}}
{"timestamp": "2025-07-19T18:48:10.136231Z", "level": "ERROR", "logger": "test_exceptions", "message": "Testing DatabaseError", "correlation_id": "c8184933-5ee5-402d-b278-adf556211356", "module": "logging_config", "function": "log_error", "line": 232, "process_id": 15344, "thread_id": 8712871680, "exception": {"type": "DatabaseError", "message": "Test database error", "traceback": "Traceback (most recent call last):\n  File \"/Users/imadeddine/Documents/GitHub/explainium-2.0/test_error_handling.py\", line 54, in test_exceptions\n    raise exc\nsrc.exceptions.DatabaseError: Test database error"}, "extra": {"taskName": null, "error_type": "DatabaseError", "error_message": "Test database error", "error_details": {"error_type": "DatabaseError", "error_code": "DatabaseError", "message": "Test database error", "details": {"operation": "test_op", "table": "test_table"}, "correlation_id": null, "timestamp": "2025-07-19T18:48:10.133974", "traceback": "NoneType: None\n"}}}
{"timestamp": "2025-07-19T18:48:10.136706Z", "level": "ERROR", "logger": "test_exceptions", "message": "Testing ProcessingError", "correlation_id": "c8184933-5ee5-402d-b278-adf556211356", "module": "logging_config", "function": "log_error", "line": 232, "process_id": 15344, "thread_id": 8712871680, "exception": {"type": "ProcessingError", "message": "Test processing error", "traceback": "Traceback (most recent call last):\n  File \"/Users/imadeddine/Documents/GitHub/explainium-2.0/test_error_handling.py\", line 54, in test_exceptions\n    raise exc\nsrc.exceptions.ProcessingError: Test processing error"}, "extra": {"taskName": null, "error_type": "ProcessingError", "error_message": "Test processing error", "error_details": {"error_type": "ProcessingError", "error_code": "ProcessingError", "message": "Test processing error", "details": {"file_path": "/test/path", "processing_stage": "test_stage"}, "correlation_id": null, "timestamp": "2025-07-19T18:48:10.134080", "traceback": "NoneType: None\n"}}}
{"timestamp": "2025-07-19T18:48:10.136980Z", "level": "ERROR", "logger": "test_exceptions", "message": "Testing AIError", "correlation_id": "c8184933-5ee5-402d-b278-adf556211356", "module": "logging_config", "function": "log_error", "line": 232, "process_id": 15344, "thread_id": 8712871680, "exception": {"type": "AIError", "message": "Test AI error", "traceback": "Traceback (most recent call last):\n  File \"/Users/imadeddine/Documents/GitHub/explainium-2.0/test_error_handling.py\", line 54, in test_exceptions\n    raise exc\nsrc.exceptions.AIError: Test AI error"}, "extra": {"taskName": null, "error_type": "AIError", "error_message": "Test AI error", "error_details": {"error_type": "AIError", "error_code": "AIError", "message": "Test AI error", "details": {"model_name": "test_model", "ai_operation": "test_operation"}, "correlation_id": null, "timestamp": "2025-07-19T18:48:10.134098", "traceback": "NoneType: None\n"}}}
{"timestamp": "2025-07-19T18:48:10.137152Z", "level": "ERROR", "logger": "test_exceptions", "message": "Testing ValidationError", "correlation_id": "c8184933-5ee5-402d-b278-adf556211356", "module": "logging_config", "function": "log_error", "line": 232, "process_id": 15344, "thread_id": 8712871680, "exception": {"type": "ValidationError", "message": "Test validation error", "traceback": "Traceback (most recent call last):\n  File \"/Users/imadeddine/Documents/GitHub/explainium-2.0/test_error_handling.py\", line 54, in test_exceptions\n    raise exc\nsrc.exceptions.ValidationError: Test validation error"}, "extra": {"taskName": null, "error_type": "ValidationError", "error_message": "Test validation error", "error_details": {"error_type": "ValidationError", "error_code": "ValidationError", "message": "Test validation error", "details": {"field": "test_field", "value": "test_value"}, "correlation_id": null, "timestamp": "2025-07-19T18:48:10.134107", "traceback": "NoneType: None\n"}}}
